<?xml version="1.0" encoding="UTF-8"?>
<testng-results skipped="0" failed="1" total="4" passed="3">
  <reporter-output>
  </reporter-output>
  <suite name="Suite" duration-ms="48946" started-at="2013-02-08T10:37:33Z" finished-at="2013-02-08T10:38:22Z">
    <groups>
    </groups>
    <test name="Test" duration-ms="48946" started-at="2013-02-08T10:37:33Z" finished-at="2013-02-08T10:38:22Z">
      <class name="testscripts.Scenario1">
        <test-method status="FAIL" signature="runTC3()[pri:0, instance:testscripts.Scenario1@1fcf0ce]" name="runTC3" duration-ms="33976" started-at="2013-02-08T16:07:33Z" finished-at="2013-02-08T16:08:07Z">
          <exception class="java.lang.AssertionError">
            <message>
              <![CDATA[Login failed for valid user]]>
            </message>
            <full-stacktrace>
              <![CDATA[java.lang.AssertionError: Login failed for valid user
	at org.testng.Assert.fail(Assert.java:94)
	at supportlibraries.DriverScript.wrapUp(DriverScript.java:515)
	at supportlibraries.DriverScript.driveTestExecution(DriverScript.java:88)
	at testscripts.Scenario1.runTC3(Scenario1.java:56)
	at sun.reflect.NativeMethodAccessorImpl.invoke0(Native Method)
	at sun.reflect.NativeMethodAccessorImpl.invoke(Unknown Source)
	at sun.reflect.DelegatingMethodAccessorImpl.invoke(Unknown Source)
	at java.lang.reflect.Method.invoke(Unknown Source)
	at org.testng.internal.MethodInvocationHelper.invokeMethod(MethodInvocationHelper.java:80)
	at org.testng.internal.Invoker.invokeMethod(Invoker.java:714)
	at org.testng.internal.Invoker.invokeTestMethod(Invoker.java:901)
	at org.testng.internal.Invoker.invokeTestMethods(Invoker.java:1231)
	at org.testng.internal.TestMethodWorker.invokeTestMethods(TestMethodWorker.java:128)
	at org.testng.internal.TestMethodWorker.run(TestMethodWorker.java:111)
	at java.util.concurrent.ThreadPoolExecutor$Worker.runTask(Unknown Source)
	at java.util.concurrent.ThreadPoolExecutor$Worker.run(Unknown Source)
	at java.lang.Thread.run(Unknown Source)
]]>
            </full-stacktrace>
          </exception> <!-- java.lang.AssertionError -->
          <reporter-output>
          </reporter-output>
        </test-method> <!-- runTC3 -->
        <test-method status="PASS" signature="runTC1()[pri:0, instance:testscripts.Scenario1@1fcf0ce]" name="runTC1" duration-ms="11603" started-at="2013-02-08T16:07:33Z" finished-at="2013-02-08T16:07:44Z">
          <reporter-output>
          </reporter-output>
        </test-method> <!-- runTC1 -->
        <test-method status="PASS" signature="runTC2()[pri:0, instance:testscripts.Scenario1@1fcf0ce]" name="runTC2" duration-ms="19475" started-at="2013-02-08T16:07:33Z" finished-at="2013-02-08T16:07:52Z">
          <reporter-output>
          </reporter-output>
        </test-method> <!-- runTC2 -->
      </class> <!-- testscripts.Scenario1 -->
      <class name="testscripts.Scenario2">
        <test-method status="PASS" signature="runTC4()[pri:0, instance:testscripts.Scenario2@eb017e]" name="runTC4" duration-ms="48936" started-at="2013-02-08T16:07:33Z" finished-at="2013-02-08T16:08:22Z">
          <reporter-output>
          </reporter-output>
        </test-method> <!-- runTC4 -->
      </class> <!-- testscripts.Scenario2 -->
    </test> <!-- Test -->
  </suite> <!-- Suite -->
</testng-results>
